#VRML_SIM V6.0 utf8
WorldInfo {
  info [
    "Description"
    "Author: first name last name <e-mail>"
    "Date: DD MMM YYYY"
  ]
  basicTimeStep 16
}
Viewpoint {
  orientation -0.0954854 -0.940531 -0.326012 1.66138
  position -0.177635 0.0918332 -0.00920025
}
Background {
  skyColor [
    0.4 0.7 1
  ]
}
DirectionalLight {
  ambientIntensity 0.5
  direction 1 -2 1
  castShadows TRUE
}
DEF FLOOR Solid {
  translation -0.5 0 -0.5
  children [
    Shape {
      geometry ElevationGrid {
        color Color {
          color [
            0.803922 0.498039 0.298039
            1 1 0
          ]
        }
        colorPerVertex FALSE
        xDimension 11
        xSpacing 0.1
        zDimension 11
        zSpacing 0.1
      }
    }
  ]
  boundingObject Transform {
    translation 0.5 0 0.5
    children [
      Plane {
      }
    ]
  }
}
DEF WALL_1 Solid {
  translation 0.5 0.05 0
  children [
    DEF WALL_SHAPE Shape {
      appearance Appearance {
        material Material {
          diffuseColor 0.12549 0.368627 0.729412
        }
      }
      geometry Box {
        size 0.02 0.1 0.98
      }
    }
  ]
  boundingObject USE WALL_SHAPE
}
DEF WALL_2 Solid {
  translation -0.5 0.05 0
  children [
    USE WALL_SHAPE
  ]
  boundingObject USE WALL_SHAPE
}
DEF WALL_3 Solid {
  translation 0 0.05 -0.5
  rotation 0 1 0 1.5708
  children [
    USE WALL_SHAPE
  ]
  boundingObject USE WALL_SHAPE
}
DEF WALL_4 Solid {
  translation 0 0.05 0.5
  rotation 0 1 0 1.5708
  children [
    USE WALL_SHAPE
  ]
  boundingObject USE WALL_SHAPE
}
DEF Cozmo Robot {
  translation 0 0.016 0
  rotation 0.996098 2.88843e-05 -0.0882487 8.46535e-06
  children [
    DEF BODY Shape {
      appearance Appearance {
        material DEF MAT_WHITE Material {
          diffuseColor 1 1 1
        }
      }
      geometry Box {
        size 0.014 0.014 0.048
      }
    }
    DEF WHEEL1 HingeJoint {
      jointParameters HingeJointParameters {
        position -1.16785e-12
        anchor 0.02 0 0.024
      }
      device RotationalMotor {
        name "wheel1"
      }
      endPoint Solid {
        translation 0.02 5.89446e-06 0.024
        rotation -0.391765 -2.85761e-05 0.920065 -1.91768e-11
        children [
          DEF WHEEL Transform {
            rotation 0 0 1 1.5708
            children [
              Shape {
                appearance Appearance {
                  material Material {
                    diffuseColor 0.254032 0.254032 0.254032
                  }
                }
                geometry Cylinder {
                  height 0.02
                  radius 0.015
                  subdivision 24
                }
              }
            ]
          }
        ]
        boundingObject USE WHEEL
        physics Physics {
        }
      }
    }
    DEF WHEEL2 HingeJoint {
      jointParameters HingeJointParameters {
        position -1.17049e-12
        anchor -0.02 0 0.024
      }
      device RotationalMotor {
        name "wheel2"
      }
      endPoint Solid {
        translation -0.02 5.89274e-06 0.024
        rotation -0.391339 -2.84768e-05 0.920247 -1.91744e-11
        children [
          USE WHEEL
        ]
        boundingObject USE WHEEL
        physics Physics {
        }
      }
    }
    DEF WHEEL3 HingeJoint {
      jointParameters HingeJointParameters {
        position 2.19839e-11
        anchor 0.02 0 -0.024
      }
      device RotationalMotor {
        name "wheel3"
      }
      endPoint Solid {
        translation 0.02 5.88652e-06 -0.024
        rotation 0.468322 2.74298e-05 -0.883558 1.99726e-11
        children [
          USE WHEEL
        ]
        boundingObject USE WHEEL
        physics Physics {
        }
      }
    }
    DEF WHEEL4 HingeJoint {
      jointParameters HingeJointParameters {
        position -1.17294e-12
        anchor -0.02 0 -0.024
      }
      device RotationalMotor {
        name "wheel4"
      }
      endPoint Solid {
        translation -0.02 5.8848e-06 -0.024
        rotation -0.391383 -2.86045e-05 0.920228 -1.91801e-11
        children [
          USE WHEEL
        ]
        boundingObject USE WHEEL
        physics Physics {
        }
      }
    }
    DEF HEAD HingeJoint {
      jointParameters HingeJointParameters {
        anchor 0 0.02 0
      }
      device RotationalMotor {
        name "motor_head_pitch"
      }
      endPoint Solid {
        rotation 1 0 0 0
        children [
          DEF EYE_LEFT Transform {
            translation -0.013 0.034 -0.01
            rotation 1 0 0 -1.5708
            children [
              DEF EYE_SHAPE Shape {
                appearance Appearance {
                  material Material {
                    diffuseColor 0.165316 0.165316 0.165316
                  }
                }
                geometry Cylinder {
                  height 0.04
                  radius 0.012
                }
              }
            ]
          }
          DEF EYE_RIGHT Transform {
            translation 0.013 0.034 -0.01
            rotation 1 0 0 -1.5708
            children [
              USE EYE_SHAPE
            ]
          }
        ]
      }
    }
    DEF BAR_LOW Transform {
      translation -0.028 0.022 0.02
      children [
        Solid {
          translation -0.003 0.006 0
          children [
            HingeJoint {
              jointParameters HingeJointParameters {
              }
              endPoint Solid {
                translation 0 0 -0.03
                rotation 1 0 0 0
                children [
                  HingeJoint {
                    jointParameters HingeJointParameters {
                      anchor 0 0 -0.03
                    }
                    endPoint DEF FRONTBARSOLID Solid {
                      translation 0.002 0.007 -0.03
                      rotation 1 0 0 0
                      children [
                        HingeJoint {
                          jointParameters HingeJointParameters {
                            anchor 0 0.007 0
                          }
                          endPoint Solid {
                            translation 0.002 0.007 0.03
                            rotation 1 0 0 0
                            children [
                              HingeJoint {
                                jointParameters HingeJointParameters {
                                  position 0.716031
                                  anchor 0 0 0.03
                                }
                                endPoint SolidReference {
                                  solidName "LiftBase"
                                }
                              }
                              Shape {
                                geometry DEF TOPBARBOX Box {
                                  size 0.001 0.004 0.06
                                }
                              }
                            ]
                            boundingObject USE TOPBARBOX
                            physics Physics {
                              centerOfMass [
                                0 0 0
                              ]
                            }
                          }
                        }
                        Shape {
                          geometry DEF FRONTBARBOX Box {
                            size 0.001 0.014 0.003
                          }
                        }
                      ]
                      name "FRONT_BAR"
                      boundingObject USE FRONTBARBOX
                      physics Physics {
                        centerOfMass [
                          0 0 0
                        ]
                      }
                    }
                  }
                  DEF LONG_BAR Shape {
                    geometry DEF LONG_BAR_BOX Box {
                      size 0.001 0.004 0.06
                    }
                  }
                ]
                boundingObject USE LONG_BAR
                physics Physics {
                  centerOfMass [
                    0 0 0
                  ]
                }
              }
            }
            Shape {
              geometry DEF LIFTBASE Box {
                size 0.01 0.02 0.01
              }
            }
          ]
          name "LiftBase"
          boundingObject USE LIFTBASE
          physics Physics {
            centerOfMass [
              0 0 0
            ]
          }
        }
      ]
    }
  ]
  name "Cozmo"
  boundingObject USE BODY
  physics Physics {
    density -1
    mass 1
  }
  controller "cozmo_controller01"
}
DEF Block1x1 Solid {
  translation 1.77879e-09 0.0299576 -0.08
  rotation 0.0372333 -0.999294 0.00497639 1.35272e-15
  children [
    DEF Block1x1Shape Shape {
      appearance Appearance {
        material Material {
          diffuseColor 1 0 0
        }
      }
      geometry Box {
        size 0.06 0.06 0.06
      }
    }
  ]
  boundingObject USE Block1x1Shape
  physics DEF Block1x1Physics Physics {
  }
}
Solid {
  translation -8.45938e-10 0.0299576 -0.2
  rotation 1.59947e-06 1 4.31414e-06 6.18763e-12
  children [
    USE Block1x1Shape
  ]
  boundingObject USE Block1x1Shape
  physics USE Block1x1Physics
}
