#VRML_SIM V6.0 utf8
WorldInfo {
  info [
    "Description"
    "Author: first name last name <e-mail>"
    "Date: DD MMM YYYY"
  ]
}
Viewpoint {
  orientation 0.449325 -0.849331 -0.277028 5.23745
  position 0.490744 0.429844 0.232682
}
Background {
  skyColor [
    0.4 0.7 1
  ]
}
PointLight {
  location 0 0.345 0
}
DEF FLOOR CheckeredFloor {
}
Solid {
  translation 0 0.1 0
  children [
    HingeJoint {
      jointParameters HingeJointParameters {
      }
      endPoint Solid {
        translation 0 0 0.05
        children [
          Shape {
            geometry DEF ARM01 Box {
              size 0.01 0.01 0.1
            }
          }
        ]
        physics Physics {
        }
      }
    }
  ]
}
